2025-06-18 23:18:01,430 [DEBUG  ] logger_config.py    :79   - 로그 파일이 다음 위치에 생성됩니다: /Volumes/mydata/personal/github/python-test/logging-test/logs/app.log
2025-06-18 23:18:01,431 [INFO   ] logging_demo.py     :32   - 애플리케이션 시작
2025-06-18 23:18:01,431 [DEBUG  ] logging_demo.py     :35   - 디버깅을 위한 상세 정보
2025-06-18 23:18:01,431 [INFO   ] logging_demo.py     :36   - 정보성 메시지
2025-06-18 23:18:01,431 [WARNING] logging_demo.py     :37   - 경고가 발생했습니다
2025-06-18 23:18:01,431 [ERROR  ] logging_demo.py     :38   - 오류가 발생했습니다
2025-06-18 23:18:01,431 [INFO   ] logging_demo.py     :44   - --------------------------------
2025-06-18 23:18:01,431 [ERROR  ] logging_demo.py     :45   - 오류 발생: division by zero
Traceback (most recent call last):
  File "/Volumes/mydata/personal/github/python-test/logging-test/src/myapp/logging_demo.py", line 42, in main
    result = 10 / 0
ZeroDivisionError: division by zero
2025-06-18 23:18:01,432 [INFO   ] logging_demo.py     :46   - --------------------------------
2025-06-18 23:20:20,467 [DEBUG  ] logger_config.py    :80   - 로그 파일이 다음 위치에 생성됩니다: /Volumes/mydata/personal/github/python-test/logging-test/logs/app.log
2025-06-18 23:20:20,467 [INFO   ] logging_demo.py     :32   - 애플리케이션 시작
2025-06-18 23:20:20,467 [DEBUG  ] logging_demo.py     :35   - 디버깅을 위한 상세 정보
2025-06-18 23:20:20,467 [INFO   ] logging_demo.py     :36   - 정보성 메시지
2025-06-18 23:20:20,467 [WARNING] logging_demo.py     :37   - 경고가 발생했습니다
2025-06-18 23:20:20,467 [ERROR  ] logging_demo.py     :38   - 오류가 발생했습니다
2025-06-18 23:20:20,467 [INFO   ] logging_demo.py     :44   - --------------------------------
2025-06-18 23:20:20,467 [ERROR  ] logging_demo.py     :45   - 오류 발생: division by zero
Traceback (most recent call last):
  File "/Volumes/mydata/personal/github/python-test/logging-test/src/myapp/logging_demo.py", line 42, in main
    result = 10 / 0
ZeroDivisionError: division by zero
2025-06-18 23:20:20,467 [INFO   ] logging_demo.py     :46   - --------------------------------
2025-06-18 23:20:21,774 [DEBUG  ] logger_config.py    :80   - 로그 파일이 다음 위치에 생성됩니다: /Volumes/mydata/personal/github/python-test/logging-test/logs/app.log
2025-06-18 23:20:21,774 [INFO   ] logging_demo.py     :32   - 애플리케이션 시작
2025-06-18 23:20:21,774 [DEBUG  ] logging_demo.py     :35   - 디버깅을 위한 상세 정보
2025-06-18 23:20:21,774 [INFO   ] logging_demo.py     :36   - 정보성 메시지
2025-06-18 23:20:21,774 [WARNING] logging_demo.py     :37   - 경고가 발생했습니다
2025-06-18 23:20:21,774 [ERROR  ] logging_demo.py     :38   - 오류가 발생했습니다
2025-06-18 23:20:21,774 [INFO   ] logging_demo.py     :44   - --------------------------------
2025-06-18 23:20:21,774 [ERROR  ] logging_demo.py     :45   - 오류 발생: division by zero
Traceback (most recent call last):
  File "/Volumes/mydata/personal/github/python-test/logging-test/src/myapp/logging_demo.py", line 42, in main
    result = 10 / 0
ZeroDivisionError: division by zero
2025-06-18 23:20:21,775 [INFO   ] logging_demo.py     :46   - --------------------------------
2025-06-18 23:20:23,530 [DEBUG  ] logger_config.py    :80   - 로그 파일이 다음 위치에 생성됩니다: /Volumes/mydata/personal/github/python-test/logging-test/logs/app.log
2025-06-18 23:20:23,530 [INFO   ] logging_demo.py     :32   - 애플리케이션 시작
2025-06-18 23:20:23,530 [DEBUG  ] logging_demo.py     :35   - 디버깅을 위한 상세 정보
2025-06-18 23:20:23,530 [INFO   ] logging_demo.py     :36   - 정보성 메시지
2025-06-18 23:20:23,530 [WARNING] logging_demo.py     :37   - 경고가 발생했습니다
2025-06-18 23:20:23,530 [ERROR  ] logging_demo.py     :38   - 오류가 발생했습니다
2025-06-18 23:20:23,531 [INFO   ] logging_demo.py     :44   - --------------------------------
2025-06-18 23:20:23,531 [ERROR  ] logging_demo.py     :45   - 오류 발생: division by zero
Traceback (most recent call last):
  File "/Volumes/mydata/personal/github/python-test/logging-test/src/myapp/logging_demo.py", line 42, in main
    result = 10 / 0
ZeroDivisionError: division by zero
2025-06-18 23:20:23,531 [INFO   ] logging_demo.py     :46   - --------------------------------
2025-06-18 23:20:47,883 [DEBUG  ] logger_config.py    :80   - 로그 파일이 다음 위치에 생성됩니다: /Volumes/mydata/personal/github/python-test/logging-test/logs/app.log
2025-06-18 23:20:47,883 [INFO   ] logging_demo.py     :32   - 애플리케이션 시작
2025-06-18 23:20:47,883 [DEBUG  ] logging_demo.py     :35   - 디버깅을 위한 상세 정보
2025-06-18 23:20:47,883 [INFO   ] logging_demo.py     :36   - 정보성 메시지
2025-06-18 23:20:47,883 [WARNING] logging_demo.py     :37   - 경고가 발생했습니다
2025-06-18 23:20:47,883 [ERROR  ] logging_demo.py     :38   - 오류가 발생했습니다
2025-06-18 23:20:47,883 [INFO   ] logging_demo.py     :44   - --------------------------------
2025-06-18 23:20:47,884 [ERROR  ] logging_demo.py     :45   - 오류 발생: division by zero
Traceback (most recent call last):
  File "/Volumes/mydata/personal/github/python-test/logging-test/src/myapp/logging_demo.py", line 42, in main
    result = 10 / 0
ZeroDivisionError: division by zero
2025-06-18 23:20:47,884 [INFO   ] logging_demo.py     :46   - --------------------------------
2025-06-18 23:20:58,213 [DEBUG  ] logger_config.py    :80   - 로그 파일이 다음 위치에 생성됩니다: /Volumes/mydata/personal/github/python-test/logging-test/logs/app.log
2025-06-18 23:20:58,213 [INFO   ] logging_demo.py     :32   - 애플리케이션 시작
2025-06-18 23:20:58,213 [DEBUG  ] logging_demo.py     :35   - 디버깅을 위한 상세 정보
2025-06-18 23:20:58,213 [INFO   ] logging_demo.py     :36   - 정보성 메시지
2025-06-18 23:20:58,213 [WARNING] logging_demo.py     :37   - 경고가 발생했습니다
2025-06-18 23:20:58,213 [ERROR  ] logging_demo.py     :38   - 오류가 발생했습니다
2025-06-18 23:20:58,213 [INFO   ] logging_demo.py     :44   - --------------------------------
2025-06-18 23:20:58,213 [ERROR  ] logging_demo.py     :45   - 오류 발생: division by zero
Traceback (most recent call last):
  File "/Volumes/mydata/personal/github/python-test/logging-test/src/myapp/logging_demo.py", line 42, in main
    result = 10 / 0
ZeroDivisionError: division by zero
2025-06-18 23:20:58,213 [INFO   ] logging_demo.py     :46   - --------------------------------
2025-06-18 23:20:59,283 [DEBUG  ] logger_config.py    :80   - 로그 파일이 다음 위치에 생성됩니다: /Volumes/mydata/personal/github/python-test/logging-test/logs/app.log
2025-06-18 23:20:59,283 [INFO   ] logging_demo.py     :32   - 애플리케이션 시작
2025-06-18 23:20:59,283 [DEBUG  ] logging_demo.py     :35   - 디버깅을 위한 상세 정보
2025-06-18 23:20:59,283 [INFO   ] logging_demo.py     :36   - 정보성 메시지
2025-06-18 23:20:59,283 [WARNING] logging_demo.py     :37   - 경고가 발생했습니다
2025-06-18 23:20:59,283 [ERROR  ] logging_demo.py     :38   - 오류가 발생했습니다
2025-06-18 23:20:59,283 [INFO   ] logging_demo.py     :44   - --------------------------------
2025-06-18 23:20:59,283 [ERROR  ] logging_demo.py     :45   - 오류 발생: division by zero
Traceback (most recent call last):
  File "/Volumes/mydata/personal/github/python-test/logging-test/src/myapp/logging_demo.py", line 42, in main
    result = 10 / 0
ZeroDivisionError: division by zero
2025-06-18 23:20:59,284 [INFO   ] logging_demo.py     :46   - --------------------------------
